Workbook

Sheet Campaign Brief Template
A5: CAMPAIGN BRIEF : SOCIAL MEDIA
A6: PLEASE FILL IN ALL HIGLIGHTED CELLS;
A7: DO NOT CHANGE CELLS THAT ARE NOT HIGHLIGHTED
A9: CAMPAIGN REQUEST: | F9: CAMPAIGN DETAILS:
A10: Sent from (Agency): | F10: Completed by (Planner):
A11: Client: | F11: Media Budget (MYR):
A12: Business Unit: | F12: Agency Commission:
A13: Date of Request (Today): | F13: Start Date:
A14: Brand / Product: | F14: End Date:
A15: Campaign Name: | F15: Length (days):
A16: Platform:
F17: Symphony E-commerce Tagging | G17: Yes / No
F19: Billing Details
F20: PO Requirement | G20: Yes / No
F21: Billing Arrangement | G21: Total Sum / Monthly
F22: Media Cost Bill To | G22: Agency / Client
F23: Media Buying Currency | G23: USD
F24: Currency Exchange Rate | G24: 4.5
F25: BCC No | G25: <To be filled by CDT>
A27: BRAND INSIGHTS:
A28: Please enter additional context or notes
A30: CAMPAIGN GOALS:
C33: CHOOSE ONE
C34: R/F Campaign | E34: OR | F34: Auction
A36: Campaign Objective | C36: ENTER HERE | F36: FB - Traffic
A38: Primary Goal* | C38: ENTER HERE | F38: [FB] Traffic - Link Clicks
A40: Secondary Goal | C40: ENTER HERE | F40: Reach
A42: KPI* | C42: CPM
A44: Target Cost Per Unit
A46: Ad Format | C46: [FB] Single Image - No CTA
A48: Instant Experience (FB only) | C48: No
A50: Agency will aim to attain Guideline Compliant R/F Campaigns (Min. Reach = 50%, Min. Freq. = 1.5x/wk) when requested
A51: However, when budget permits Auction-based campaigns will be recommended
A53: MEASUREMENT
A54: Campaign goal tracking required (e.g. conversion/remarketing/event) | D54: Yes/No | F54: Conversion
A55: Will this campaign be measured? | D55: Yes/No | F55: What will the study measure? Insert here
A56: Measurement Partner: | D56: Millward Brown / MOAT
A57: 3rd Party Measurement Rate: | D57: <specify cost per unit.> | F57: <insert the rates here>
A59: TARGETING:
A60: TARGET OPTION 1 | E60: NOTES
...

Sheet Tactical Reco Template
A1: Agency Logo | B1: Brand: | C1: ='Campaign Brief Template'!C14 -> 0
B2: Campaign: | C2: ='Campaign Brief Template'!C15 -> 0
B3: Platform: | C3: ='Campaign Brief Template'!C16 -> 0
B5: Autofill | F5: Agency to fill out | L5: Autofill
B6: Platform | C6: Objective | D6: Buying Type | E6: Target Audience | F6: Recommended Flight | G6: Audience Size | H6: Estimated Website Clicks | I6: Estimated Cost Per Website Click | J6: Estimated Impressions | K6: Estimated CPM | L6: Media Budget | N6: Campaign Budget
A7: Auction Campaigns | B7: ='Campaign Brief Template'!C16 -> 0 | C7: ='Campaign Brief Template'!F36 -> FB - Traffic | D7: ='Campaign Brief Template'!F34 -> Auction | E7: ='Campaign Brief Template'!C61 -> 25-50 | F7: 4 weeks | G7: 43030914 | H7: =L7/I7 -> #DIV/0! | I7: 0 | K7: 0 | N7: =SUM(L7:M7) -> 0
E8: ='Campaign Brief Template'!C62 -> Male and Female
B10: ='Campaign Brief Template'!C16 -> 0 | C10: ='Campaign Brief Template'!F36 -> FB - Traffic | D10: ='Campaign Brief Template'!F34 -> Auction | F10: 4 weeks | G10: 43030914 | H10: =L7/I10 -> #DIV/0! | I10: 0 | K10: 0
E11: 18-35
E12: Female
B14: Autofill | F14: Agency to fill out | N14: Autofill
A15: Reach and Frequency Campaigns | B15: Platform | C15: Objective | D15: Buying Type | E15: Target Audience | F15: Recommended Flight | G15: Audience Size | H15: Estimated % Reach* | I15: Estimated # Reach | J15: Weekly Frequency | K15: Estimated Frequency | L15: Estimated Impressions | M15: Estimated CPM | N15: Media Budget | P15: Campaign Budget
B16: ='Campaign Brief Template'!C16 -> 0 | C16: ='Campaign Brief Template'!C36 -> ENTER HERE | D16: ='Campaign Brief Template'!C34 -> R/F Campaign | E16: ='Campaign Brief Template'!C61 -> 25-50 | F16: 4 weeks | G16: 43030914 | J16: =K16/8 -> 0.55 | K16: 4.4 | M16: 0
E17: ='Campaign Brief Template'!C62 -> Male and Female
B19: ='Campaign Brief Template'!C16 -> 0 | C19: ='Campaign Brief Template'!C36 -> ENTER HERE | D19: ='Campaign Brief Template'!C34 -> R/F Campaign | F19: 4 weeks | G19: 43030914 | J19: =K19/8 -> 0.625 | K19: 5 | M19: 0
E20: 18-35
E21: Female
A25: Screenshot of R&F Simulation Graph

Sheet Tags
B1: Brand: | C1: ='Campaign Brief Template'!C14 -> 0
B2: Campaign: | C2: ='Campaign Brief Template'!C15 -> 0
B3: Platform: | C3: ='Campaign Brief Template'!C16 -> 0
B6: Nielsen Tag | C6: Sizmek Tag
A7: English Audience
B13: Nielsen Tag | C13: Sizmek Tag
A14: French Audience

Sheet Creative Intake Template
B1: Brand: | C1: ='Request for Proposal-Client'!C14
B2: Campaign: | C2: ='Request for Proposal-Client'!C15
B3: Budget:
E5: Autofill | H5: Autofill | J5: Autofill | L5: Autofill | S5: Agency Fill out | W5: Agency Fill out
A6: Platform | B6: Targeting | C6: Ad | D6: Ad Type | E6: Flight Start | F6: Flight End | G6: Copy | H6: Characters (Limit 90) | I6: Headline | J6: Characters (Limit 25) | K6: News Feed Link Description (Desktop Ads Only) | L6: Characters (Limit 30) | M6: Display Link (For Website Click Campaigns Only) | N6: Website URL (For Website Click Campaigns Only) | O6: CTA (For Website Click Campaigns Only) | P6: Asset Name | Q6: Length | R6: Neilsen Tag | S6: Demo Link | T6: Date Mocked | U6: Screenshot | V6: Client Approval | W6: Confirm Live Date | X6: Confirm Ended Date | Y6: Reasoning, If different from planned Flight Start / Flight End
A7: Facebook | B7: Target 1 | C7: #1 | D7: Photo | E7: ='Request for Proposal-Client'!G12 | F7: ='Request for Proposal-Client'!G13 | G7: This is the main copy of the advertisement. | H7: =IF((LEN(G7)<90),LEN(G7),"TOO LONG") -> 43 | I7: This is a headline | J7: =IF((LEN(I7)<25),LEN(I7),"TOO LONG") -> 18 | K7: This is a newsfeed link description. | L7: =IF((LEN(K7)<30),LEN(K7),"TOO LONG") -> TOO LONG | O7: Learn More | P7: EXAMPLE:Garnier Video 1 | Q7: :15 | S7: Agency will supply the Demo link here for approval | T7: 42736 | U7: Agency will provide screenshot of the live ad here
A8: Facebook | B8: Target 2 | C8: #2 | D8: Photo | E8: ='Request for Proposal-Client'!G12 | F8: ='Request for Proposal-Client'!G13 | G8: This is the main copy of the advertisement. | H8: =IF((LEN(G8)<90),LEN(G8),"TOO LONG") -> 43 | I8: This is a headline | J8: =IF((LEN(I8)<25),LEN(I8),"TOO LONG") -> 18 | K8: This is a newsfeed link description. | L8: =IF((LEN(K8)<30),LEN(K8),"TOO LONG") -> TOO LONG | O8: Learn More | Q8: :30 | S8: BN will supply the Demo link here for approval | T8: 42736 | U8: BN will provide screenshot of the live ad here
A9: Instagram | B9: Target 1 | C9: #3 | D9: Video | E9: ='Request for Proposal-Client'!G12 | F9: ='Request for Proposal-Client'!G13 | G9: This is the main copy of the advertisement. | H9: =IF((LEN(G9)<90),LEN(G9),"TOO LONG") -> 43 | I9: This is a headline | J9: =IF((LEN(I9)<25),LEN(I9),"TOO LONG") -> 18 | K9: This is a newsfeed link description. | L9: =IF((LEN(K9)<30),LEN(K9),"TOO LONG") -> TOO LONG | O9: Learn More | P9: Garnier Video 3 | Q9: :30 | S9: BN will supply the Demo link here for approval | T9: 42736 | U9: BN will provide screenshot of the live ad here
A10: Instagram | B10: Target 2 | C10: #4 | D10: Video | E10: ='Request for Proposal-Client'!G12 | F10: ='Request for Proposal-Client'!G13 | G10: This is the main copy of the advertisement. | H10: =IF((LEN(G10)<90),LEN(G10),"TOO LONG") -> 43 | I10: This is a headline | J10: =IF((LEN(I10)<25),LEN(I10),"TOO LONG") -> 18 | K10: This is a newsfeed link description. | L10: =IF((LEN(K10)<30),LEN(K10),"TOO LONG") -> TOO LONG | O10: Learn More | P10: Garnier Video 4 | Q10: :120 | S10: Agency will supply the Demo link here for approval | T10: 42736 | U10: Agency will provide screenshot of the live ad here

Sheet Sheet5
A1: Campaign Objective (Auction) | B1: Campaign Objective (R&F) | C1: Primary Goal | D1: Standard Optimizations | E1: Secondary Goal | H1: KPI | J1: Ad Format
A2: ENTER HERE | B2: ENTER HERE | C2: Reach | D2: Reach | E2: Reach | F2: Reach | H2: CPM | J2: [FB] Single Image - No CTA | L2: Yes
A3: FB - Brand Awareness | B3: FB - Brand Awareness | C3: Impressions | D3: Impressions | E3: Impressions | F3: ENTER HERE | H3: CPE | J3: [FB] Single Video - No CTA | L3: No
A4: FB - Reach | B4: FB - Reach | C4: Brand Awareness | D4: Clicks | E4: Brand Awareness | H4: CPA | J4: [FB] Single Image - CTA | L4: ENTER HERE
A5: FB - Traffic | B5: FB - Traffic | C5: Video Views | D5: Page Engagement | E5: Video Views | H5: CPV | J5: [FB] Single Video - CTA
A6: FB - Engagement | B6: FB - Engagement | C6: App Engagement | D6: Like | E6: Clicks | H6: CPC | J6: [FB] Collection
A7: FB - App Installs | B7: FB - App Installs | C7: App Installs | D7: Mention | E7: App Engagement | H7: Cost Per Install | J7: [FB] Carousel
A8: FB - Video Views | B8: FB - Video Views | C8: Website Conversions | D8: Comment | E8: App Installs | H8: Cost Per Lead | J8: [TW] Carousel Website Card - Video
A9: FB - Lead Generation | B9: FB - Conversions | C9: [FB] Thruplay | D9: Post Engagement | E9: Website Conversions | H9: [FB] CPV - 2 Seconds | J9: [TW] Carousel Website Card - Image
A10: FB - Message | C10: [FB] 2-Second Continuos Video View | D10: Post Like | E10: [FB] Thruplay | H10: [FB] CPV - ThruPlay | J10: [TW] Carousel App Card - Video
A11: FB - Conversions | C11: [FB] Store Visit | D11: Photo View | E11: [FB] 2-Second Continuos Video View | H11: [FB] Cost Per Landing | J11: [TW] Carousel App Card - Image
A12: FB - Catalogue Sales | C12: [FB] Engagement - Post Engagement | D12: Video Play | E12: [FB] Store Visit | H12: [FB] CPC (Link Clicks) | J12: [TW] Promoted Text
A13: FB - Store Traffics | C13: [FB] Engagement - Page Likes | D13: Video View | E13: [FB] Engagement - Post Engagement | H13: [FB] Cost Per Lead | J13: [TW] Promoted Image
A14: FB - Conversions (CPAS) | C14: [FB] Engagement - Event Response | D14: Video 25% watched | E14: [FB] Engagement - Page Likes | H14: [FB] Cost Per Event Response | J14: [TW] Promoted GIF
A15: FB - Catalogue Sales (CPAS) | C15: [FB] Traffic - Link Clicks | D15: Video 50% watched | E15: [FB] Event Response - Page Likes | H15: [FB] Cost Per Conversation / Message | J15: [TW] Promoted Poll
A16: Twitter - Reach | C16: [FB] Traffic - Landing Page Views | D16: Video 75% watched | E16: [FB] Traffic - Link Clicks | H16: [TW] CPAC (Cost Per App Click) | J16: [TW] Promoted Card
A17: Twitter - Video Views | C17: [FB] Lead Generation | D17: Video 95% watched | E17: [FB] Traffic - Landing Page Views | H17: [TW] CPV - 2 Seconds | J17: [TW] First View
A18: Twitter - Pre-roll Views | C18: [FB] Conversation - Messenger / Whatsapp / Instagram Direct | D18: Video 100% watched | E18: [FB] Lead Generation | H18: [TW] CPV - 3 Seconds | J18: [TW] Promoted Trend
A19: Twitter - App Installs | C19: [FB] CPAS - View Content | D19: Video Complete | E19: [FB] Conversation - Messenger / Whatsapp / Instagram Direct | H19: [TW] CPV - 6 Seconds | J19: [TW] Website Card - Video
A20: Twitter - Website Clicks | C20: [FB] CPAS - Add To Cart | D20: Video :10s Watch | E20: [FB] CPAS - View Content | H20: [TikTok] CPV - 2 Seconds | J20: [TW] Website Card - Image
A21: Twitter - Engagements | C21: [FB] CPAS - Purchase | D21: Video :15s Watch | E21: [FB] CPAS - Add To Cart | H21: [TikTok] CPV - 6 Seconds | J21: [TW] App Card - Video
A22: Twitter - Followers | C22: [FB] CPAS - ROAS | D22: Video :30s Watch | E22: [FB] CPAS - Purchase | H22: ENTER HERE | J22: [TW] App Card - Image
A23: Twitter - App Re-engagement | C23: [Twitter] Followers | D23: Link Click | E23: [FB] CPAS - ROAS | J23: [TW] Conversational Card - Video
A24: TikTok - Reach | C24: ENTER HERE | D24: Offsite Conversion: Custom Event | E24: [Twitter] Followers | J24: [TW] Conversational Card - Image
A25: TikTok - Traffic | D25: Mobile App Install | E25: Photo View | J25: [TW] Tweet to Unlock - Image
A26: TikTok - App Installs | D26: Mobile App Custom Event | E26: Video Play | J26: [TW] Tweet to Unlock - Video
A27: TikTok - Video Views | D27: ENTER HERE | E27: Video View | J27: [TikTok] Native In-Feed Ads - Video
A28: TikTok - Conversions | E28: Video 25% watched | J28: [LinkedIn] Single Image Ad
A29: LinkedIn - Brand Awareness | E29: Video 50% watched | J29: [LinkedIn] Carousel Image Ad
A30: LinkedIn - Website Visits | E30: Video 75% watched | J30: [LinkedIn] Video Ad
A31: LinkedIn - Engagement | E31: Video 95% watched | J31: [LinkedIn] Text Ad
A32: LinkedIn - Video View | E32: Video 100% watched | J32: [LinkedIn] Spotlight Ad
A33: LinkedIn - Lead Generation | E33: Video Complete | J33: [LinkedIn] Follower Ad
A34: LinkedIn - Website Conversions | E34: Video :10s Watch | J34: [LinkedIn] Conversation Ad
A35: LinkedIn - Job Applicants | E35: Video :15s Watch | J35: ENTER HERE
E36: Video :30s Watch

Sheet Sheet1

Sheet Launch Checklist
A2: Item | B2: Confirmation (+ initials) | C2: Date
A3: Media Plan Approval
A4: IO
A5: Tags
A6: Mock Approval
A7: Study Setup Complete
